Workbook

Sheet Cleaned_Data-Practice
A1: Customer_ID_Clean | B1: Account_Number | C1: Customer_Name_Clean | D1: Transaction_Date | E1: Transaction_Type_Clean | F1: Amount_Clean | G1: Currency | H1: Branch_Code_Clean | I1: Transaction_ID | J1: Notes_Clean | K1: Column1
A2: =IF(LEFT(TRIM(Raw_Data!A2),5)="CUST-",UPPER(TRIM(Raw_Data!A2)),"CUST-"&UPPER(TRIM(Raw_Data!A2))) -> CUST-1001 | B2: =Raw_Data!B2 -> ACC-884521 | C2: =PROPER(TRIM(CLEAN(Raw_Data!C2))) -> Priya Sharma | D2: =Raw_Data!D2 -> 2026-08-01 | E2: =PROPER(TRIM(Raw_Data!E2)) -> Credit | F2: =IFERROR(VALUE(SUBSTITUTE(SUBSTITUTE(TRIM(Raw_Data!F2),"$",""),",","")),"CHECK") -> 15000 | G2: =Raw_Data!G2 -> INR | H2: =IF(TRIM(Raw_Data!H2)="","UNKNOWN",TRIM(Raw_Data!H2)) -> BRN-01 | I2: =Raw_Data!I2 -> TXN-0001 | J2: =PROPER(TRIM(CLEAN(Raw_Data!J2))) -> Salary Credit For August | L2: =IF(COUNTIF($J$2:J2,J2)>1,"DUPLICATE","OK") -> OK | M2: =M4 -> 0
A3: =IF(LEFT(TRIM(Raw_Data!A3),5)="CUST-",UPPER(TRIM(Raw_Data!A3)),"CUST-"&UPPER(TRIM(Raw_Data!A3))) -> CUST-1002 | B3: =Raw_Data!B3 -> ACC-774832 | C3: =PROPER(TRIM(CLEAN(Raw_Data!C3))) -> Rahul Mehta | D3: =Raw_Data!D3 -> 2026-08-02 | E3: =PROPER(TRIM(Raw_Data!E3)) -> Debit | F3: =IFERROR(VALUE(SUBSTITUTE(SUBSTITUTE(TRIM(Raw_Data!F3),"$",""),",","")),"CHECK") -> 8500 | G3: =Raw_Data!G3 -> INR | H3: =IF(TRIM(Raw_Data!H3)="","UNKNOWN",TRIM(Raw_Data!H3)) -> BRN-02 | I3: =Raw_Data!I3 -> TXN-0002 | J3: =PROPER(TRIM(CLEAN(Raw_Data!J3))) -> Online Transfer To Vendor | L3: =IF(COUNTIF($J$2:J3,J3)>1,"DUPLICATE","OK") -> OK
A4: =IF(LEFT(TRIM(Raw_Data!A4),5)="CUST-",UPPER(TRIM(Raw_Data!A4)),"CUST-"&UPPER(TRIM(Raw_Data!A4))) -> CUST-1003 | B4: =Raw_Data!B4 -> ACC-663741 | C4: =PROPER(TRIM(CLEAN(Raw_Data!C4))) -> Ananya Iyer | D4: =Raw_Data!D4 -> 01/08/2026 | E4: =PROPER(TRIM(Raw_Data!E4)) -> Credit | F4: =IFERROR(VALUE(SUBSTITUTE(SUBSTITUTE(TRIM(Raw_Data!F4),"$",""),",","")),"CHECK") -> 22000 | G4: =Raw_Data!G4 -> INR | H4: =IF(TRIM(Raw_Data!H4)="","UNKNOWN",TRIM(Raw_Data!H4)) -> UNKNOWN | I4: =Raw_Data!I4 -> TXN-0003 | J4: =PROPER(TRIM(CLEAN(Raw_Data!J4))) -> Loan Disbursement [Sys] | L4: =IF(COUNTIF($J$2:J4,J4)>1,"DUPLICATE","OK") -> OK
A5: =IF(LEFT(TRIM(Raw_Data!A5),5)="CUST-",UPPER(TRIM(Raw_Data!A5)),"CUST-"&UPPER(TRIM(Raw_Data!A5))) -> CUST-1004 | B5: =Raw_Data!B5 -> ACC-552630 | C5: =PROPER(TRIM(CLEAN(Raw_Data!C5))) -> Vikram Singh | D5: =Raw_Data!D5 -> 2026-08-04 | E5: =PROPER(TRIM(Raw_Data!E5)) -> Debit | F5: =IFERROR(VALUE(SUBSTITUTE(SUBSTITUTE(TRIM(Raw_Data!F5),"$",""),",","")),"CHECK") -> 3750 | G5: =Raw_Data!G5 -> INR | H5: =IF(TRIM(Raw_Data!H5)="","UNKNOWN",TRIM(Raw_Data!H5)) -> BRN-01 | I5: =Raw_Data!I5 -> TXN-0004 | J5: =PROPER(TRIM(CLEAN(Raw_Data!J5))) -> Atm Withdrawal | L5: =IF(COUNTIF($J$2:J5,J5)>1,"DUPLICATE","OK") -> OK
A6: =IF(LEFT(TRIM(Raw_Data!A6),5)="CUST-",UPPER(TRIM(Raw_Data!A6)),"CUST-"&UPPER(TRIM(Raw_Data!A6))) -> CUST-1005 | B6: =Raw_Data!B6 -> ACC-441519 | C6: =PROPER(TRIM(CLEAN(Raw_Data!C6))) -> Sneha Nair | D6: =Raw_Data!D6 -> 2026-08-05 | E6: =PROPER(TRIM(Raw_Data!E6)) -> Credit | F6: =IFERROR(VALUE(SUBSTITUTE(SUBSTITUTE(TRIM(Raw_Data!F6),"$",""),",","")),"CHECK") -> 9800 | G6: =Raw_Data!G6 -> INR | H6: =IF(TRIM(Raw_Data!H6)="","UNKNOWN",TRIM(Raw_Data!H6)) -> BRN-03 | I6: =Raw_Data!I6 -> TXN-0003 | J6: =PROPER(TRIM(CLEAN(Raw_Data!J6))) -> Freelance Payment Received | L6: =IF(COUNTIF($J$2:J6,J6)>1,"DUPLICATE","OK") -> OK
A7: =IF(LEFT(TRIM(Raw_Data!A7),5)="CUST-",UPPER(TRIM(Raw_Data!A7)),"CUST-"&UPPER(TRIM(Raw_Data!A7))) -> CUST-CUST -1006 | B7: =Raw_Data!B7 -> ACC-330408 | C7: =PROPER(TRIM(CLEAN(Raw_Data!C7))) -> Amit Patel | D7: =Raw_Data!D7 -> 2026-08-06 | E7: =PROPER(TRIM(Raw_Data!E7)) -> Debit | F7: =IFERROR(VALUE(SUBSTITUTE(SUBSTITUTE(TRIM(Raw_Data!F7),"$",""),",","")),"CHECK") -> 1200.5 | G7: =Raw_Data!G7 -> INR | H7: =IF(TRIM(Raw_Data!H7)="","UNKNOWN",TRIM(Raw_Data!H7)) -> BRN-02 | I7: =Raw_Data!I7 -> TXN-0006 | J7: =PROPER(TRIM(CLEAN(Raw_Data!J7))) -> Utility Bill Payment | L7: =IF(COUNTIF($J$2:J7,J7)>1,"DUPLICATE","OK") -> OK
A8: =IF(LEFT(TRIM(Raw_Data!A8),5)="CUST-",UPPER(TRIM(Raw_Data!A8)),"CUST-"&UPPER(TRIM(Raw_Data!A8))) -> CUST-1007 | B8: =Raw_Data!B8 -> ACC-229397 | C8: =PROPER(TRIM(CLEAN(Raw_Data!C8))) -> Ritu Gupta | D8: =Raw_Data!D8 -> 2026-08-07 | E8: =PROPER(TRIM(Raw_Data!E8)) -> Debit | F8: =IFERROR(VALUE(SUBSTITUTE(SUBSTITUTE(TRIM(Raw_Data!F8),"$",""),",","")),"CHECK") -> 500 | G8: =Raw_Data!G8 -> INR | H8: =IF(TRIM(Raw_Data!H8)="","UNKNOWN",TRIM(Raw_Data!H8)) -> BRN-04 | I8: =Raw_Data!I8 -> TXN-0007 | J8: =PROPER(TRIM(CLEAN(Raw_Data!J8))) -> Coffee Shop Payment | L8: =IF(COUNTIF($J$2:J8,J8)>1,"DUPLICATE","OK") -> OK
A9: =IF(LEFT(TRIM(Raw_Data!A9),5)="CUST-",UPPER(TRIM(Raw_Data!A9)),"CUST-"&UPPER(TRIM(Raw_Data!A9))) -> CUST-1008 | B9: =Raw_Data!B9 -> ACC-118286 | C9: =PROPER(TRIM(CLEAN(Raw_Data!C9))) -> Deepak Verma | D9: =Raw_Data!D9 -> 08-Aug-2026 | E9: =PROPER(TRIM(Raw_Data!E9)) -> Credit | F9: =IFERROR(VALUE(SUBSTITUTE(SUBSTITUTE(TRIM(Raw_Data!F9),"$",""),",","")),"CHECK") -> 45000 | G9: =Raw_Data!G9 -> INR | H9: =IF(TRIM(Raw_Data!H9)="","UNKNOWN",TRIM(Raw_Data!H9)) -> UNKNOWN | I9: =Raw_Data!I9 -> TXN-0008 | J9: =PROPER(TRIM(CLEAN(Raw_Data!J9))) -> Property Rent Collected Extra | L9: =IF(COUNTIF($J$2:J9,J9)>1,"DUPLICATE","OK") -> OK
A10: =IF(LEFT(TRIM(Raw_Data!A10),5)="CUST-",UPPER(TRIM(Raw_Data!A10)),"CUST-"&UPPER(TRIM(Raw_Data!A10))) -> CUST-1009 | B10: =Raw_Data!B10 -> ACC-007175 | C10: =PROPER(TRIM(CLEAN(Raw_Data!C10))) -> Meena Krishnan | D10: =Raw_Data!D10 -> 2026-08-09 | E10: =PROPER(TRIM(Raw_Data!E10)) -> Debit | F10: =IFERROR(VALUE(SUBSTITUTE(SUBSTITUTE(TRIM(Raw_Data!F10),"$",""),",","")),"CHECK") -> 2300 | G10: =Raw_Data!G10 -> INR | H10: =IF(TRIM(Raw_Data!H10)="","UNKNOWN",TRIM(Raw_Data!H10)) -> BRN-03 | I10: =Raw_Data!I10 -> TXN-0009 | J10: =PROPER(TRIM(CLEAN(Raw_Data!J10))) -> Insurance Premium Paid | L10: =IF(COUNTIF($J$2:J10,J10)>1,"DUPLICATE","OK") -> OK
A11: =IF(LEFT(TRIM(Raw_Data!A11),5)="CUST-",UPPER(TRIM(Raw_Data!A11)),"CUST-"&UPPER(TRIM(Raw_Data!A11))) -> CUST-1010 | B11: =Raw_Data!B11 -> ACC-996064 | C11: =PROPER(TRIM(CLEAN(Raw_Data!C11))) -> Arjun Bose | D11: =Raw_Data!D11 -> 2026-08-10 | E11: =PROPER(TRIM(Raw_Data!E11)) -> Credit | F11: =IFERROR(VALUE(SUBSTITUTE(SUBSTITUTE(TRIM(Raw_Data!F11),"$",""),",","")),"CHECK") -> 11000 | G11: =Raw_Data!G11 -> INR | H11: =IF(TRIM(Raw_Data!H11)="","UNKNOWN",TRIM(Raw_Data!H11)) -> BRN-01 | I11: =Raw_Data!I11 -> TXN-0010 | J11: =PROPER(TRIM(CLEAN(Raw_Data!J11))) -> Dividend Received | L11: =IF(COUNTIF($J$2:J11,J11)>1,"DUPLICATE","OK") -> OK
A12: =IF(LEFT(TRIM(Raw_Data!A12),5)="CUST-",UPPER(TRIM(Raw_Data!A12)),"CUST-"&UPPER(TRIM(Raw_Data!A12))) -> CUST-1011 | B12: =Raw_Data!B12 -> ACC-885953 | C12: =PROPER(TRIM(CLEAN(Raw_Data!C12))) -> Kavya Reddy | D12: =Raw_Data!D12 -> 2026-08-11 | E12: =PROPER(TRIM(Raw_Data!E12)) -> Debit | F12: =IFERROR(VALUE(SUBSTITUTE(SUBSTITUTE(TRIM(Raw_Data!F12),"$",""),",","")),"CHECK") -> 750 | G12: =Raw_Data!G12 -> INR | H12: =IF(TRIM(Raw_Data!H12)="","UNKNOWN",TRIM(Raw_Data!H12)) -> BRN-05 | I12: =Raw_Data!I12 -> TXN-0011 | J12: =PROPER(TRIM(CLEAN(Raw_Data!J12))) -> Supermarket Purchase | L12: =IF(COUNTIF($J$2:J12,J12)>1,"DUPLICATE","OK") -> OK
A13: =IF(LEFT(TRIM(Raw_Data!A13),5)="CUST-",UPPER(TRIM(Raw_Data!A13)),"CUST-"&UPPER(TRIM(Raw_Data!A13))) -> CUST-1012 | B13: =Raw_Data!B13 -> ACC-774842 | C13: =PROPER(TRIM(CLEAN(Raw_Data!C13))) -> Suresh Pillai | D13: =Raw_Data!D13 -> 2026-08-12 | E13: =PROPER(TRIM(Raw_Data!E13)) -> Credit | F13: CHECK | G13: =Raw_Data!G13 -> INR | H13: =IF(TRIM(Raw_Data!H13)="","UNKNOWN",TRIM(Raw_Data!H13)) -> BRN-02 | I13: =Raw_Data!I13 -> TXN-0012 | J13: =PROPER(TRIM(CLEAN(Raw_Data!J13))) -> Pending Credit | L13: =IF(COUNTIF($J$2:J13,J13)>1,"DUPLICATE","OK") -> OK
A14: =IF(LEFT(TRIM(Raw_Data!A14),5)="CUST-",UPPER(TRIM(Raw_Data!A14)),"CUST-"&UPPER(TRIM(Raw_Data!A14))) -> CUST-1003 | B14: =Raw_Data!B14 -> ACC-663741 | C14: =PROPER(TRIM(CLEAN(Raw_Data!C14))) -> Ananya Iyer | D14: =Raw_Data!D14 -> 01/08/2026 | E14: =PROPER(TRIM(Raw_Data!E14)) -> Credit | F14: =IFERROR(VALUE(SUBSTITUTE(SUBSTITUTE(TRIM(Raw_Data!F14),"$",""),",","")),"CHECK") -> 22000 | G14: =Raw_Data!G14 -> INR | H14: =IF(TRIM(Raw_Data!H14)="","UNKNOWN",TRIM(Raw_Data!H14)) -> UNKNOWN | I14: =Raw_Data!I14 -> TXN-0003 | J14: =PROPER(TRIM(CLEAN(Raw_Data!J14))) -> Loan Disbursement | L14: =IF(COUNTIF($J$2:J14,J14)>1,"DUPLICATE","OK") -> OK
A15: =IF(LEFT(TRIM(Raw_Data!A15),5)="CUST-",UPPER(TRIM(Raw_Data!A15)),"CUST-"&UPPER(TRIM(Raw_Data!A15))) -> CUST-1013 | B15: =Raw_Data!B15 -> ACC-553731 | C15: =PROPER(TRIM(CLEAN(Raw_Data!C15))) -> Pooja Desai | D15: =Raw_Data!D15 -> 2026-08-14 | E15: =PROPER(TRIM(Raw_Data!E15)) -> Debit | F15: =IFERROR(VALUE(SUBSTITUTE(SUBSTITUTE(TRIM(Raw_Data!F15),"$",""),",","")),"CHECK") -> 4200 | G15: =Raw_Data!G15 -> INR | H15: =IF(TRIM(Raw_Data!H15)="","UNKNOWN",TRIM(Raw_Data!H15)) -> BRN-04 | I15: =Raw_Data!I15 -> TXN-0013 | J15: =PROPER(TRIM(CLEAN(Raw_Data!J15))) -> Emi Payment | L15: =IF(COUNTIF($J$2:J15,J15)>1,"DUPLICATE","OK") -> OK
A16: =IF(LEFT(TRIM(Raw_Data!A16),5)="CUST-",UPPER(TRIM(Raw_Data!A16)),"CUST-"&UPPER(TRIM(Raw_Data!A16))) -> CUST-1014 | B16: =Raw_Data!B16 -> ACC-442620 | C16: =PROPER(TRIM(CLEAN(Raw_Data!C16))) -> Nikhil Joshi | D16: =Raw_Data!D16 -> 2026-08-15 | E16: =PROPER(TRIM(Raw_Data!E16)) -> Credit | F16: =IFERROR(VALUE(SUBSTITUTE(SUBSTITUTE(TRIM(Raw_Data!F16),"$",""),",","")),"CHECK") -> 18900 | G16: =Raw_Data!G16 -> INR | H16: =IF(TRIM(Raw_Data!H16)="","UNKNOWN",TRIM(Raw_Data!H16)) -> BRN-01 | I16: =Raw_Data!I16 -> TXN-0014 | J16: =PROPER(TRIM(CLEAN(Raw_Data!J16))) -> Consulting Fees | L16: =IF(COUNTIF($J$2:J16,J16)>1,"DUPLICATE","OK") -> OK
A17: =IF(LEFT(TRIM(Raw_Data!A17),5)="CUST-",UPPER(TRIM(Raw_Data!A17)),"CUST-"&UPPER(TRIM(Raw_Data!A17))) -> CUST-1015 | B17: =Raw_Data!B17 -> ACC-331509 | C17: =PROPER(TRIM(CLEAN(Raw_Data!C17))) -> Preethi Menon | D17: =Raw_Data!D17 -> 2026-08-16 | E17: =PROPER(TRIM(Raw_Data!E17)) -> Debit | F17: =IFERROR(VALUE(SUBSTITUTE(SUBSTITUTE(TRIM(Raw_Data!F17),"$",""),",","")),"CHECK") -> 250 | G17: =Raw_Data!G17 -> INR | H17: =IF(TRIM(Raw_Data!H17)="","UNKNOWN",TRIM(Raw_Data!H17)) -> UNKNOWN | I17: =Raw_Data!I17 -> TXN-0015 | J17: =PROPER(TRIM(CLEAN(Raw_Data!J17))) -> Food Delivery | L17: =IF(COUNTIF($J$2:J17,J17)>1,"DUPLICATE","OK") -> OK
A18: =IF(LEFT(TRIM(Raw_Data!A18),5)="CUST-",UPPER(TRIM(Raw_Data!A18)),"CUST-"&UPPER(TRIM(Raw_Data!A18))) -> CUST-1016 | B18: =Raw_Data!B18 -> ACC-220398 | C18: =PROPER(TRIM(CLEAN(Raw_Data!C18))) -> Rohit Kumar | D18: =Raw_Data!D18 -> 2026-08-17 | E18: =PROPER(TRIM(Raw_Data!E18)) -> Credit | F18: =IFERROR(VALUE(SUBSTITUTE(SUBSTITUTE(TRIM(Raw_Data!F18),"$",""),",","")),"CHECK") -> 8000 | G18: =Raw_Data!G18 -> INR | H18: =IF(TRIM(Raw_Data!H18)="","UNKNOWN",TRIM(Raw_Data!H18)) -> BRN-03 | I18: =Raw_Data!I18 -> TXN-0016 | J18: =PROPER(TRIM(CLEAN(Raw_Data!J18))) -> Part-Time Income | L18: =IF(COUNTIF($J$2:J18,J18)>1,"DUPLICATE","OK") -> OK
A19: =IF(LEFT(TRIM(Raw_Data!A19),5)="CUST-",UPPER(TRIM(Raw_Data!A19)),"CUST-"&UPPER(TRIM(Raw_Data!A19))) -> CUST-1002 | B19: =Raw_Data!B19 -> ACC-774832 | C19: =PROPER(TRIM(CLEAN(Raw_Data!C19))) -> Rahul Mehta | D19: =Raw_Data!D19 -> 2026-08-02 | E19: =PROPER(TRIM(Raw_Data!E19)) -> Debit | F19: =IFERROR(VALUE(SUBSTITUTE(SUBSTITUTE(TRIM(Raw_Data!F19),"$",""),",","")),"CHECK") -> 8500 | G19: =Raw_Data!G19 -> INR | H19: =IF(TRIM(Raw_Data!H19)="","UNKNOWN",TRIM(Raw_Data!H19)) -> BRN-02 | I19: =Raw_Data!I19 -> TXN-0002 | J19: =PROPER(TRIM(CLEAN(Raw_Data!J19))) -> Online Transfer To Vendor | L19: =IF(COUNTIF($J$2:J19,J19)>1,"DUPLICATE","OK") -> DUPLICATE
A20: =IF(LEFT(TRIM(Raw_Data!A20),5)="CUST-",UPPER(TRIM(Raw_Data!A20)),"CUST-"&UPPER(TRIM(Raw_Data!A20))) -> CUST-1017 | B20: =Raw_Data!B20 -> ACC-119287 | C20: =PROPER(TRIM(CLEAN(Raw_Data!C20))) -> Lakshmi Rao | D20: =Raw_Data!D20 -> 2026-08-19 | E20: =PROPER(TRIM(Raw_Data!E20)) -> Debit | F20: =IFERROR(VALUE(SUBSTITUTE(SUBSTITUTE(TRIM(Raw_Data!F20),"$",""),",","")),"CHECK") -> 1050 | G20: =Raw_Data!G20 -> INR | H20: =IF(TRIM(Raw_Data!H20)="","UNKNOWN",TRIM(Raw_Data!H20)) -> BRN-05 | I20: =Raw_Data!I20 -> TXN-0017 | J20: =PROPER(TRIM(CLEAN(Raw_Data!J20))) -> Mobile Recharge | L20: =IF(COUNTIF($J$2:J20,J20)>1,"DUPLICATE","OK") -> OK
A21: =IF(LEFT(TRIM(Raw_Data!A21),5)="CUST-",UPPER(TRIM(Raw_Data!A21)),"CUST-"&UPPER(TRIM(Raw_Data!A21))) -> CUST-1018 | B21: =Raw_Data!B21 -> ACC-008176 | C21: =PROPER(TRIM(CLEAN(Raw_Data!C21))) -> Harsh Vardhan | D21: =Raw_Data!D21 -> 2026-08-20 | E21: =PROPER(TRIM(Raw_Data!E21)) -> Credit | F21: =IFERROR(VALUE(SUBSTITUTE(SUBSTITUTE(TRIM(Raw_Data!F21),"$",""),",","")),"CHECK") -> 30000 | G21: =Raw_Data!G21 -> INR | H21: =IF(TRIM(Raw_Data!H21)="","UNKNOWN",TRIM(Raw_Data!H21)) -> BRN-02 | I21: =Raw_Data!I21 -> TXN-0018 | J21: =PROPER(TRIM(CLEAN(Raw_Data!J21))) -> Quarterly Bonus | L21: =IF(COUNTIF($J$2:J21,J21)>1,"DUPLICATE","OK") -> OK
A22: =IF(LEFT(TRIM(Raw_Data!A22),5)="CUST-",UPPER(TRIM(Raw_Data!A22)),"CUST-"&UPPER(TRIM(Raw_Data!A22))) -> CUST-1019 | B22: =Raw_Data!B22 -> ACC-997065 | C22: =PROPER(TRIM(CLEAN(Raw_Data!C22))) -> Divya Nambiar | D22: =Raw_Data!D22 -> 21-Aug-2026 | E22: =PROPER(TRIM(Raw_Data!E22)) -> Debit | F22: =IFERROR(VALUE(SUBSTITUTE(SUBSTITUTE(TRIM(Raw_Data!F22),"$",""),",","")),"CHECK") -> 600 | G22: =Raw_Data!G22 -> INR | H22: =IF(TRIM(Raw_Data!H22)="","UNKNOWN",TRIM(Raw_Data!H22)) -> UNKNOWN | I22: =Raw_Data!I22 -> TXN-0019 | J22: =PROPER(TRIM(CLEAN(Raw_Data!J22))) -> Grocery Shopping | L22: =IF(COUNTIF($J$2:J22,J22)>1,"DUPLICATE","OK") -> OK
A23: =IF(LEFT(TRIM(Raw_Data!A23),5)="CUST-",UPPER(TRIM(Raw_Data!A23)),"CUST-"&UPPER(TRIM(Raw_Data!A23))) -> CUST-1020 | B23: =Raw_Data!B23 -> ACC-886954 | C23: =PROPER(TRIM(CLEAN(Raw_Data!C23))) -> Sanjay Kapoor | D23: =Raw_Data!D23 -> 2026-08-22 | E23: =PROPER(TRIM(Raw_Data!E23)) -> Credit | F23: =IFERROR(VALUE(SUBSTITUTE(SUBSTITUTE(TRIM(Raw_Data!F23),"$",""),",","")),"CHECK") -> 5500 | G23: =Raw_Data!G23 -> INR | H23: =IF(TRIM(Raw_Data!H23)="","UNKNOWN",TRIM(Raw_Data!H23)) -> BRN-01 | I23: =Raw_Data!I23 -> TXN-0020 | J23: =PROPER(TRIM(CLEAN(Raw_Data!J23))) -> Freelance Invoice | L23: =IF(COUNTIF($J$2:J23,J23)>1,"DUPLICATE","OK") -> OK
A24: =IF(LEFT(TRIM(Raw_Data!A24),5)="CUST-",UPPER(TRIM(Raw_Data!A24)),"CUST-"&UPPER(TRIM(Raw_Data!A24))) -> CUST-1021 | B24: =Raw_Data!B24 -> ACC-775843 | C24: =PROPER(TRIM(CLEAN(Raw_Data!C24))) -> Radha Krishna | D24: =Raw_Data!D24 -> 2026-08-23 | E24: =PROPER(TRIM(Raw_Data!E24)) -> Credit | F24: =IFERROR(VALUE(SUBSTITUTE(SUBSTITUTE(TRIM(Raw_Data!F24),"$",""),",","")),"CHECK") -> 12750 | G24: =Raw_Data!G24 -> INR | H24: =IF(TRIM(Raw_Data!H24)="","UNKNOWN",TRIM(Raw_Data!H24)) -> BRN-03 | I24: =Raw_Data!I24 -> TXN-0021 | J24: =PROPER(TRIM(CLEAN(Raw_Data!J24))) -> Rental Income | L24: =IF(COUNTIF($J$2:J24,J24)>1,"DUPLICATE","OK") -> OK
A25: =IF(LEFT(TRIM(Raw_Data!A25),5)="CUST-",UPPER(TRIM(Raw_Data!A25)),"CUST-"&UPPER(TRIM(Raw_Data!A25))) -> CUST-1022 | B25: =Raw_Data!B25 -> ACC-664732 | C25: =PROPER(TRIM(CLEAN(Raw_Data!C25))) -> Mohan Lal | D25: =Raw_Data!D25 -> 2026-08-24 | E25: =PROPER(TRIM(Raw_Data!E25)) -> Debit | F25: =IFERROR(VALUE(SUBSTITUTE(SUBSTITUTE(TRIM(Raw_Data!F25),"$",""),",","")),"CHECK") -> 900 | G25: =Raw_Data!G25 -> INR | H25: =IF(TRIM(Raw_Data!H25)="","UNKNOWN",TRIM(Raw_Data!H25)) -> BRN-04 | I25: =Raw_Data!I25 -> TXN-0022 | J25: =PROPER(TRIM(CLEAN(Raw_Data!J25))) -> Book Purchase | L25: =IF(COUNTIF($J$2:J25,J25)>1,"DUPLICATE","OK") -> OK
... A31: =IF(LEFT(TRIM(Raw_Data!A31),5)="CUST-",UPPER(TRIM(Raw_Data!A31)),"CUST-"&UPPER(TRIM(Raw_Data!A31))) -> CUST-1028 | B31: =Raw_Data!B31 -> ACC-008066 | C31: =PROPER(TRIM(CLEAN(Raw_Data!C31))) -> Rajan Pillai | D31: =Raw_Data!D31 -> 25/08/2026 | E31: =PROPER(TRIM(Raw_Data!E31)) -> Credit | F31: =IFERROR(VALUE(SUBSTITUTE(SUBSTITUTE(TRIM(Raw_Data!F31),"$",""),",","")),"CHECK") -> 14000 | G31: =Raw_Data!G31 -> INR | H31: =IF(TRIM(Raw_Data!H31)="","UNKNOWN",TRIM(Raw_Data!H31)) -> BRN-04 | I31: =Raw_Data!I31 -> TXN-0028 | J31: =PROPER(TRIM(CLEAN(Raw_Data!J31))) -> Salary Advance | L31: =IF(COUNTIF($J$2:J31,J31)>1,"DUPLICATE","OK") -> OK
A33: 💡 Blue cells = Excel formulas (click to see) | After removing duplicates from Raw_Data, re-check which rows disappear here | Column D (Date): practice Text-to-Columns & date formatting manually in Excel
A35: 🏆 CHALLENGE TASKS — Complete these without hints
A36: C1 | B36: Count how many Customer_IDs were missing the 'CUST-' prefix in Raw_Data | G36: Hint: COUNTIF + wildcard on Raw_Data!A:A
A37: C2 | B37: Count rows where Branch_Code was blank in Raw_Data | G37: Hint: COUNTBLANK(Raw_Data!H2:H31)
A38: C3 | B38: Calculate total Amount after cleaning (exclude 'CHECK' errors) | G38: Hint: SUMIF on column F of this sheet
A39: C4 | B39: Find how many duplicate Transaction_IDs exist in Raw_Data | G39: Hint: COUNTIF(Raw_Data!I:I, Raw_Data!I2) > 1
A40: C5 | B40: List unique Transaction_Types using PROPER casing | G40: Hint: Use Remove Duplicates on a copy of col E
A42: Your answers (type formulas in column B beside each challenge number above):
C46: =SUMIF(E3:E32,"Credit",F3:F32)/SUM(F3:F32) -> 0.86282034

Sheet Address Effect
E4: S.No | F4: Name | G4: Bank Balance | H4: Interest | I4: Total(Relative) | J4: Total (Absolute)
E5: 1 | F5: James | G5: 10000 | H5: 0.5 | I5: =G5+H5 -> 10000.5 | J5: =$G$5 *10 -> 100000
E6: 2 | F6: Mary | G6: 12330 | H6: 0.4 | I6: =G6+H6 -> 12330.4 | J6: =$G$5 *10 -> 100000
E7: 3 | F7: Gary | G7: 34555 | H7: 0.6 | I7: =G7+H7 -> 34555.6 | J7: =$G$5 *10 -> 100000
E8: 4 | F8: Rosell | G8: 456566 | H8: 0.7 | I8: =G8+H8 -> 456566.7 | J8: =$G$5 *10 -> 100000
E9: 5 | F9: John | G9: 34534 | H9: 0.2 | I9: =G9+H9 -> 34534.2 | J9: =$G$5 *10 -> 100000
E10: 6 | F10: Simmi | G10: 50000 | H10: 0.5 | I10: =G10+H10 -> 50000.5 | J10: =$G$5 *10 -> 100000
E11: 7 | F11: Amayra | G11: 78900 | H11: 0.4 | I11: =G11+H11 -> 78900.4 | J11: =$G$5 *10 -> 100000
E12: 8 | F12: Ryan | G12: 765476 | H12: 0.3 | I12: =G12+H12 -> 765476.3 | J12: =$G$5 *10 -> 100000
E13: 9 | F13: Charles | G13: 234324 | H13: 0.9 | I13: =G13+H13 -> 234324.9 | J13: =$G$5 *10 -> 100000
E14: 10 | F14: Jenny | G14: 97979 | H14: 0.2 | I14: =G14+H14 -> 97979.2 | J14: =$G$5 *10 -> 100000
F21: 46235

Sheet Instructions
B1: KPMG Operations Analyst – Week 1 | Data Cleaning Practice
B2: Wednesday Session | Trainer Workbook
B4: 📋 What's in this workbook?
B5: Raw_Data sheet → 30 rows of messy banking transaction records with 8 data quality issues built in. Cleaned_Data sheet → Your practice area. Formulas are partially pre-filled; complete the rest as instructed.
B7: 🔧 Tasks & Formulas to Practice
B8: Task / Issue | C8: What to do | D8: Formula to use
B9: 1. Remove Duplicates | C9: Transaction_ID column has duplicate entries. Use Data → Remove Duplicates. | D9: Data tab → Remove Duplicates
B10: 2. Extra Spaces (TRIM) | C10: Customer names and notes have leading/trailing/double spaces. | D10: =TRIM(Raw_Data!C2) -> Priya Sharma
B11: 3. Non-printable chars (CLEAN) | C11: Notes column contains hidden characters that came from a system export. | D11: =CLEAN(TRIM(Raw_Data!J2)) -> Salary credit for August
B12: 4. Fix Casing (PROPER) | C12: Customer names and transaction types are in ALL CAPS or all lower. | D12: =PROPER(TRIM(Raw_Data!C2)) -> Priya Sharma
B13: 5. Text to Columns | C13: Column K has 'Name | DOB' combined. Split on '|' using Data → Text to Columns. | D13: Data tab → Text to Columns → Delimited → |
B14: 6. Handle Blanks | C14: Branch_Code has empty cells. Replace blanks with 'UNKNOWN' using IF. | D14: =IF(Raw_Data!H2="","UNKNOWN",Raw_Data!H2) -> BRN-01
B15: 7. Standardize IDs | C15: Customer_ID format is inconsistent (some miss 'CUST-' prefix, spaces inside). | D15: =IF(LEFT(TRIM(Raw_Data!A2),5)="CUST-",UPPER(TRIM(Raw_Data!A2)),"CUST-"&UPPER(TRIM(Raw_Data!A2))) -> CUST-1001
B16: 8. Standardize Financial Fields | C16: Amount column has $, commas, and text mixed. Convert to clean numbers. | D16: =VALUE(SUBSTITUTE(SUBSTITUTE(TRIM(Raw_Data!F2),"$",""),",","")) -> 15000
B18: ✅ Color Legend (Raw_Data sheet)
B19: 🔴 Red fill | C19: Duplicate rows
B20: 🟡 Yellow fill | C20: Blank / missing values
B21: 🟠 Orange text | C21: Inconsistent format (IDs, dates, amounts)
B22: ⬜ No fill | C22: Normal data (some issues may not be highlighted — find them!)

Sheet Raw_Data (2)
A1: Customer_ID | B1: Account_Number | C1: Customer_Name | D1: Transaction_Date | E1: Transaction_Type | F1: Amount | G1: Currency | H1: Branch_Code | I1: Transaction_ID | J1: Notes | K1: Name_DOB_Combined | M1: Date | O1: Check Date
A2: CUST-1001 | B2: ACC-884521 | C2: Priya Sharma | D2: 2026-08-01 | E2: Credit | F2: 15000 | G2: INR | H2: BRN-01 | I2: TXN-0001 | J2: Salary credit for August | K2: Priya Sharma | 1990-04-12 | M2: 01/08/2026 | O2: =IF(ISNUMBER(M2),"Valid Date","Not a Date") -> Not a Date
A3: CUST-1002 | B3: ACC-774832 | C3: RAHUL MEHTA | D3: 2026-08-02 | E3: DEBIT | F3: $8,500.00 | G3: INR | H3: BRN-02 | I3: TXN-0002 | J3: Online transfer to vendor | K3: RAHUL MEHTA | 1985-11-30
A4: 1003 | B4: ACC-663741 | C4: ananya iyer | D4: 01/08/2026 | E4: credit | F4: 22000 | G4: INR | I4: TXN-0003 | J4: Loan disbursement [SYS] | K4: ananya iyer | 1993-07-08
A5: CUST-1004 | B5: ACC-552630 | C5: Vikram Singh | D5: 2026-08-04 | E5: Debit | F5: 3750 | G5: INR | H5: BRN-01 | I5: TXN-0004 | J5: ATM withdrawal | K5: Vikram Singh | 1978-02-25
A6: CUST-1005 | B6: ACC-441519 | C6: Sneha Nair | D6: 2026-08-05 | E6: Credit | F6: 9800 | G6: INR | H6: BRN-03 | I6: TXN-0003 | J6: Freelance payment received | K6: Sneha Nair | 1995-09-14
A7: CUST -1006 | B7: ACC-330408 | C7: AMIT PATEL | D7: 46240 | E7: DEBIT | F7: 1,200.50 | G7: INR | H7: BRN-02 | I7: TXN-0006 | J7: Utility bill payment | K7: AMIT PATEL | 1982-06-03
A8: CUST-1007 | B8: ACC-229397 | C8: ritu gupta | D8: 2026-08-07 | E8: debit | F8: 500 | G8: INR | H8: BRN-04 | I8: TXN-0007 | J8: Coffee shop payment | K8: ritu gupta | 1999-12-20 | L8: =ISNUMBER(D8) | M8: =ISNUMBER(D8) -> FALSE | N8: =DATEVALUE(D8) | O8: =DATEVALUE(D8) -> 46241 | P8: =ISNUMBER(O6) | Q8: =ISNUMBER(O8) -> TRUE
A9: CUST-1008 | B9: ACC-118286 | C9: Deepak Verma | D9: 08-Aug-2026 | E9: Credit | F9: $45,000 | G9: INR | I9: TXN-0008 | J9: Property rent collected extra | K9: Deepak Verma | 1975-03-17
A10: CUST-1009 | B10: ACC-007175 | C10: MEENA KRISHNAN | D10: 46243 | E10: Debit | F10: $2,300.00 | G10: INR | H10: BRN-03 | I10: TXN-0009 | J10: Insurance premium paid | K10: MEENA KRISHNAN | 1988-08-05 | L10: =DATE(LEFT(D10,4),MID(D10,6,2),RIGHT(D10,2)) | M10: =DATE(LEFT(D10,4),MID(D10,6,2),RIGHT(D10,2)) -> #VALUE! | N10: =Isnumber(D10) | O10: =ISNUMBER(D10) -> TRUE | P10: Isnumber(M10) | Q10: =ISNUMBER(M10) -> FALSE
A11: CUST-1010 | B11: ACC-996064 | C11: Arjun Bose | D11: 2026-08-10 | E11: Credit | F11: 11000 | G11: INR | H11: BRN-01 | I11: TXN-0010 | J11: Dividend received | K11: Arjun Bose | 1991-01-22
A12: 1011 | B12: ACC-885953 | C12: kavya reddy | D12: 2026-08-11 | E12: debit | F12: 750 | G12: INR | H12: BRN-05 | I12: TXN-0011 | J12: Supermarket purchase | K12: kavya reddy | 1996-05-09
A13: CUST-1012 | B13: ACC-774842 | C13: SURESH PILLAI | D13: 2026-08-12 | E13: Credit | F13: N/A | G13: INR | H13: BRN-02 | I13: TXN-0012 | J13: Pending credit | K13: SURESH PILLAI | 1970-10-31
A14: 1003 | B14: ACC-663741 | C14: ananya iyer | D14: 01/08/2026 | E14: credit | F14: 22000 | G14: INR | I14: TXN-0003 | J14: Loan disbursement | K14: ananya iyer | 1993-07-08 | L14: =DATE(RIGHT(D14,4),MID(D14,4,2),LEFT(D14,2)) | M14: =DATE(RIGHT(D14,4),MID(D14,4,2),LEFT(D14,2)) -> 46235 | P14: =ISNUMBER(M14) | Q14: =ISNUMBER(M14) -> TRUE
A15: CUST-1013 | B15: ACC-553731 | C15: Pooja Desai | D15: 2026-08-14 | E15: Debit | F15: 4200 | G15: INR | H15: BRN-04 | I15: TXN-0013 | J15: EMI payment | K15: Pooja Desai | 1987-02-14
A16: CUST-1014 | B16: ACC-442620 | C16: NIKHIL JOSHI | D16: 2026-08-15 | E16: CREDIT | F16: $18,900 | G16: INR | H16: BRN-01 | I16: TXN-0014 | J16: Consulting fees | K16: NIKHIL JOSHI | 1983-07-07
A17: 1015 | B17: ACC-331509 | C17: preethi menon | D17: 2026-08-16 | E17: debit | F17: 250 | G17: INR | I17: TXN-0015 | J17: Food delivery | K17: preethi menon | 2000-11-11
A18: CUST-1016 | B18: ACC-220398 | C18: Rohit Kumar | D18: 2026-08-17 | E18: Credit | F18: 8000 | G18: INR | H18: BRN-03 | I18: TXN-0016 | J18: Part-time income | K18: Rohit Kumar | 1994-08-19
A19: CUST-1002 | B19: ACC-774832 | C19: RAHUL MEHTA | D19: 2026-08-02 | E19: DEBIT | F19: $8,500.00 | G19: INR | H19: BRN-02 | I19: TXN-0002 | J19: Online transfer to vendor | K19: RAHUL MEHTA | 1985-11-30
A20: CUST-1017 | B20: ACC-119287 | C20: LAKSHMI RAO | D20: 2026-08-19 | E20: Debit | F20: 1,050 | G20: INR | H20: BRN-05 | I20: TXN-0017 | J20: Mobile recharge | K20: LAKSHMI RAO | 1979-04-28
A21: CUST-1018 | B21: ACC-008176 | C21: Harsh Vardhan | D21: 2026-08-20 | E21: Credit | F21: 30000 | G21: INR | H21: BRN-02 | I21: TXN-0018 | J21: Quarterly bonus | K21: Harsh Vardhan | 1986-09-16
A22: CUST-1019 | B22: ACC-997065 | C22: DIVYA NAMBIAR | D22: 21-Aug-2026 | E22: DEBIT | F22: $600 | G22: INR | I22: TXN-0019 | J22: Grocery shopping | K22: DIVYA NAMBIAR | 1992-03-03
A23: CUST-1020 | B23: ACC-886954 | C23: sanjay kapoor | D23: 2026-08-22 | E23: credit | F23: 5500 | G23: INR | H23: BRN-01 | I23: TXN-0020 | J23: Freelance invoice | K23: sanjay kapoor | 1989-12-25
A24: CUST-1021 | B24: ACC-775843 | C24: RADHA KRISHNA | D24: 2026-08-23 | E24: Credit | F24: 12,750 | G24: INR | H24: BRN-03 | I24: TXN-0021 | J24: Rental income | K24: RADHA KRISHNA | 1976-06-30
A25: 1022 | B25: ACC-664732 | C25: mohan lal | D25: 2026-08-24 | E25: debit | F25: 900 | G25: INR | H25: BRN-04 | I25: TXN-0022 | J25: Book purchase | K25: mohan lal | 1998-01-15
A26: CUST-1023 | B26: ACC-553621 | C26: Geeta Pillai | D26: 2026-08-25 | E26: Debit | F26: 2100 | G26: INR | I26: TXN-0023 | J26: School fees | K26: Geeta Pillai | 1984-05-02
A27: CUST -1024 | B27: ACC-442510 | C27: KIRAN BHAT | D27: 2026-08-25 | E27: CREDIT | F27: $7,200.00 | G27: INR | H27: BRN-02 | I27: TXN-0024 | J27: Dividend credit | K27: KIRAN BHAT | 1981-08-21
A28: CUST-1025 | B28: ACC-331399 | C28: nisha thomas | D28: 2026-08-25 | E28: debit | F28: $350 | G28: INR | H28: BRN-05 | I28: TXN-0025 | J28: Streaming subscription | K28: nisha thomas | 2001-03-07
A29: CUST-1026 | B29: ACC-220288 | C29: VISHAL AGARWAL | D29: 2026-08-25 | E29: Credit | F29: 25000 | G29: INR | H29: BRN-01 | I29: TXN-0026 | J29: Project bonus | K29: VISHAL AGARWAL | 1977-11-18
A30: CUST-1027 | B30: ACC-119177 | C30: Sunita Rao | D30: 2026-08-25 | E30: Debit | F30: 1800 | G30: INR | H30: BRN-03 | I30: TXN-0027 | J30: Monthly subscription | K30: Sunita Rao | 1993-06-06
A31: 1028 | B31: ACC-008066 | C31: rajan pillai | D31: 25/08/2026 | E31: credit | F31: 14000 | G31: INR | H31: BRN-04 | I31: TXN-0028 | J31: Salary advance | K31: rajan pillai | 1980-09-29
A33: LEGEND: 🔴 Pink fill = Duplicate row | 🟡 Yellow fill = Blank value | 🟠 Orange text = Inconsistent format | Find hidden chars & spacing issues in Notes column
D34: IsNumbe

Sheet Sheet1
A1: Customer_ID_Clean | B1: Account_Number | C1: Customer_Name_Clean | D1: Transaction_Date | E1: Transaction_Type_Clean | F1: Amount_Clean | G1: Currency | H1: Branch_Code_Clean | I1: Transaction_ID | J1: Notes_Clean | K1: Status | L1: Count Total Amount | M1: Total Amount | N1: Average of amount | O1: Is number | P1: Is it a Text | Q1: Count Non Empty Amount | R1: Max Amount | S1: Min Amount | T1: Count Credit Transaction | U1: Debit count | V1: Total Credit Value | W1: Total Debit Value | X1: Find duplicate transaction | Y1: Finds unknown branch codes | Z1: Finds invalid amount entries | AA1: Find Duplicate Transaction ID | AB1: Check Duplication Customer ID | AC1: Check duplicate transactions (Same customerid and transactionid)
A2: =IF(LEFT(TRIM([1]Raw_Data!A7),5)="CUST-",UPPER(TRIM([1]Raw_Data!A7)),"CUST-"&UPPER(TRIM([1]Raw_Data!A7))) -> CUST-CUST -1006 | B2: =[1]Raw_Data!B7 -> ACC-330408 | C2: =PROPER(TRIM(CLEAN([1]Raw_Data!C7))) -> Amit Patel | D2: =[1]Raw_Data!D7 -> 2026-08-06 | E2: =PROPER(TRIM([1]Raw_Data!E7)) -> Debit | F2: =IFERROR(VALUE(SUBSTITUTE(SUBSTITUTE(TRIM([1]Raw_Data!F7),"$",""),",","")),"CHECK") -> 1200.5 | G2: =[1]Raw_Data!G7 -> INR | H2: =IF(TRIM([1]Raw_Data!H7)="","UNKNOWN",TRIM([1]Raw_Data!H7)) -> BRN-02 | I2: =[1]Raw_Data!I7 -> TXN-0006 | J2: =PROPER(TRIM(CLEAN([1]Raw_Data!J7))) -> Utility Bill Payment | K2: =IF(COUNTIF($J$2:J2,J2)>1,"DUPLICATE","OK") -> OK | L2: =COUNT(F2:F31) -> 29 | M2: =SUM(F2:F31) -> 281900.5 | N2: =AVERAGE(F2:F31) -> 9720.7069 | O2: =ISNUMBER(F2) -> TRUE | P2: =ISTEXT(F2) -> FALSE | Q2: =COUNTA(F2:F31) -> 30 | R2: =MAX(F2:F31) -> 45000 | S2: =MIN(F2:F31) -> 250 | T2: =COUNTIF(E2:E31,"Credit") -> 15 | U2: =COUNTIF(E2:E31,"Debit") -> 15 | V2: =SUMIF(E2:E31,"Credit",F2:F31) -> 245150 | W2: =SUMIF(E2:E31,"Debit",F2:F31) -> 36750.5 | X2: =IF(COUNTIF(I2:I31,I2)>1,"Duplicate","Unique") -> Unique | Y2: =COUNTIF(H2:H31,"UNKNOWN") -> 6 | Z2: =COUNTIF(F2:F31,"CHECK") -> 1 | AA2: =COUNTIF(I:I,I2) -> 1 | AB2: =COUNTIF(A:A,A2) -> 1 | AC2: =COUNTIFS(A:A,A2,I:I,I2) -> 1
A3: =IF(LEFT(TRIM([1]Raw_Data!A4),5)="CUST-",UPPER(TRIM([1]Raw_Data!A4)),"CUST-"&UPPER(TRIM([1]Raw_Data!A4))) -> CUST-1003 | B3: =[1]Raw_Data!B4 -> ACC-663741 | C3: =PROPER(TRIM(CLEAN([1]Raw_Data!C4))) -> Ananya Iyer | D3: =[1]Raw_Data!D4 -> 01/08/2026 | E3: =PROPER(TRIM([1]Raw_Data!E4)) -> Credit | F3: =IFERROR(VALUE(SUBSTITUTE(SUBSTITUTE(TRIM([1]Raw_Data!F4),"$",""),",","")),"CHECK") -> 22000 | G3: =[1]Raw_Data!G4 -> INR | H3: =IF(TRIM([1]Raw_Data!H4)="","UNKNOWN",TRIM([1]Raw_Data!H4)) -> UNKNOWN | I3: =[1]Raw_Data!I4 -> TXN-0003 | J3: =PROPER(TRIM(CLEAN([1]Raw_Data!J4))) -> Loan Disbursement [Sys] | K3: =IF(COUNTIF($J$2:J3,J3)>1,"DUPLICATE","OK") -> OK | X3: =IF(COUNTIF(I3:I32,I3)>1,"Duplicate","Unique") -> Duplicate | AA3: =COUNTIF(I:I,I3) -> 3 | AB3: =COUNTIF(A:A,A3) -> 2 | AC3: =COUNTIFS(A:A,A3,I:I,I3) -> 2
A4: =IF(LEFT(TRIM([1]Raw_Data!A14),5)="CUST-",UPPER(TRIM([1]Raw_Data!A14)),"CUST-"&UPPER(TRIM([1]Raw_Data!A14))) -> CUST-1003 | B4: =[1]Raw_Data!B14 -> ACC-663741 | C4: =PROPER(TRIM(CLEAN([1]Raw_Data!C14))) -> Ananya Iyer | D4: =[1]Raw_Data!D14 -> 01/08/2026 | E4: =PROPER(TRIM([1]Raw_Data!E14)) -> Credit | F4: 21000 | G4: =[1]Raw_Data!G14 -> INR | H4: =IF(TRIM([1]Raw_Data!H14)="","UNKNOWN",TRIM([1]Raw_Data!H14)) -> UNKNOWN | I4: =[1]Raw_Data!I14 -> TXN-0003 | J4: =PROPER(TRIM(CLEAN([1]Raw_Data!J14))) -> Loan Disbursement | K4: =IF(COUNTIF($J$2:J4,J4)>1,"DUPLICATE","OK") -> OK | X4: =IF(COUNTIF(I4:I33,I4)>1,"Duplicate","Unique") -> Duplicate | AA4: =COUNTIF(I:I,I4) -> 3 | AB4: =COUNTIF(A:A,A4) -> 2 | AC4: =COUNTIFS(A:A,A4,I:I,I4) -> 2
A5: =IF(LEFT(TRIM([1]Raw_Data!A11),5)="CUST-",UPPER(TRIM([1]Raw_Data!A11)),"CUST-"&UPPER(TRIM([1]Raw_Data!A11))) -> CUST-1010 | B5: =[1]Raw_Data!B11 -> ACC-996064 | C5: =PROPER(TRIM(CLEAN([1]Raw_Data!C11))) -> Arjun Bose | D5: =[1]Raw_Data!D11 -> 2026-08-10 | E5: =PROPER(TRIM([1]Raw_Data!E11)) -> Credit | F5: =IFERROR(VALUE(SUBSTITUTE(SUBSTITUTE(TRIM([1]Raw_Data!F11),"$",""),",","")),"CHECK") -> 11000 | G5: =[1]Raw_Data!G11 -> INR | H5: =IF(TRIM([1]Raw_Data!H11)="","UNKNOWN",TRIM([1]Raw_Data!H11)) -> BRN-01 | I5: =[1]Raw_Data!I11 -> TXN-0010 | J5: =PROPER(TRIM(CLEAN([1]Raw_Data!J11))) -> Dividend Received | K5: =IF(COUNTIF($J$2:J5,J5)>1,"DUPLICATE","OK") -> OK | X5: =IF(COUNTIF(I5:I34,I5)>1,"Duplicate","Unique") -> Unique | AA5: =COUNTIF(I:I,I5) -> 1 | AB5: =COUNTIF(A:A,A5) -> 1 | AC5: =COUNTIFS(A:A,A5,I:I,I5) -> 1
A6: =IF(LEFT(TRIM([1]Raw_Data!A9),5)="CUST-",UPPER(TRIM([1]Raw_Data!A9)),"CUST-"&UPPER(TRIM([1]Raw_Data!A9))) -> CUST-1008 | B6: =[1]Raw_Data!B9 -> ACC-118286 | C6: =PROPER(TRIM(CLEAN([1]Raw_Data!C9))) -> Deepak Verma | D6: =[1]Raw_Data!D9 -> 08-Aug-2026 | E6: =PROPER(TRIM([1]Raw_Data!E9)) -> Credit | F6: =IFERROR(VALUE(SUBSTITUTE(SUBSTITUTE(TRIM([1]Raw_Data!F9),"$",""),",","")),"CHECK") -> 45000 | G6: =[1]Raw_Data!G9 -> INR | H6: =IF(TRIM([1]Raw_Data!H9)="","UNKNOWN",TRIM([1]Raw_Data!H9)) -> UNKNOWN | I6: =[1]Raw_Data!I9 -> TXN-0008 | J6: =PROPER(TRIM(CLEAN([1]Raw_Data!J9))) -> Property Rent Collected Extra | K6: =IF(COUNTIF($J$2:J6,J6)>1,"DUPLICATE","OK") -> OK | X6: =IF(COUNTIF(I6:I35,I6)>1,"Duplicate","Unique") -> Unique | AA6: =COUNTIF(I:I,I6) -> 1 | AB6: =COUNTIF(A:A,A6) -> 1 | AC6: =COUNTIFS(A:A,A6,I:I,I6) -> 1
A7: =IF(LEFT(TRIM([1]Raw_Data!A22),5)="CUST-",UPPER(TRIM([1]Raw_Data!A22)),"CUST-"&UPPER(TRIM([1]Raw_Data!A22))) -> CUST-1019 | B7: =[1]Raw_Data!B22 -> ACC-997065 | C7: =PROPER(TRIM(CLEAN([1]Raw_Data!C22))) -> Divya Nambiar | D7: =[1]Raw_Data!D22 -> 21-Aug-2026 | E7: =PROPER(TRIM([1]Raw_Data!E22)) -> Debit | F7: =IFERROR(VALUE(SUBSTITUTE(SUBSTITUTE(TRIM([1]Raw_Data!F22),"$",""),",","")),"CHECK") -> 600 | G7: =[1]Raw_Data!G22 -> INR | H7: =IF(TRIM([1]Raw_Data!H22)="","UNKNOWN",TRIM([1]Raw_Data!H22)) -> UNKNOWN | I7: =[1]Raw_Data!I22 -> TXN-0019 | J7: =PROPER(TRIM(CLEAN([1]Raw_Data!J22))) -> Grocery Shopping | K7: =IF(COUNTIF($J$2:J7,J7)>1,"DUPLICATE","OK") -> OK | X7: =IF(COUNTIF(I7:I36,I7)>1,"Duplicate","Unique") -> Unique | AA7: =COUNTIF(I:I,I7) -> 1 | AB7: =COUNTIF(A:A,A7) -> 1 | AC7: =COUNTIFS(A:A,A7,I:I,I7) -> 1
A8: =IF(LEFT(TRIM([1]Raw_Data!A26),5)="CUST-",UPPER(TRIM([1]Raw_Data!A26)),"CUST-"&UPPER(TRIM([1]Raw_Data!A26))) -> CUST-1023 | B8: =[1]Raw_Data!B26 -> ACC-553621 | C8: =PROPER(TRIM(CLEAN([1]Raw_Data!C26))) -> Geeta Pillai | D8: =[1]Raw_Data!D26 -> 2026-08-25 | E8: =PROPER(TRIM([1]Raw_Data!E26)) -> Debit | F8: =IFERROR(VALUE(SUBSTITUTE(SUBSTITUTE(TRIM([1]Raw_Data!F26),"$",""),",","")),"CHECK") -> 2100 | G8: =[1]Raw_Data!G26 -> INR | H8: =IF(TRIM([1]Raw_Data!H26)="","UNKNOWN",TRIM([1]Raw_Data!H26)) -> UNKNOWN | I8: =[1]Raw_Data!I26 -> TXN-0023 | J8: =PROPER(TRIM(CLEAN([1]Raw_Data!J26))) -> School Fees | K8: =IF(COUNTIF($J$2:J8,J8)>1,"DUPLICATE","OK") -> OK | X8: =IF(COUNTIF(I8:I37,I8)>1,"Duplicate","Unique") -> Unique | AA8: =COUNTIF(I:I,I8) -> 1 | AB8: =COUNTIF(A:A,A8) -> 1 | AC8: =COUNTIFS(A:A,A8,I:I,I8) -> 1
A9: =IF(LEFT(TRIM([1]Raw_Data!A21),5)="CUST-",UPPER(TRIM([1]Raw_Data!A21)),"CUST-"&UPPER(TRIM([1]Raw_Data!A21))) -> CUST-1018 | B9: =[1]Raw_Data!B21 -> ACC-008176 | C9: =PROPER(TRIM(CLEAN([1]Raw_Data!C21))) -> Harsh Vardhan | D9: =[1]Raw_Data!D21 -> 2026-08-20 | E9: =PROPER(TRIM([1]Raw_Data!E21)) -> Credit | F9: =IFERROR(VALUE(SUBSTITUTE(SUBSTITUTE(TRIM([1]Raw_Data!F21),"$",""),",","")),"CHECK") -> 30000 | G9: =[1]Raw_Data!G21 -> INR | H9: =IF(TRIM([1]Raw_Data!H21)="","UNKNOWN",TRIM([1]Raw_Data!H21)) -> BRN-02 | I9: =[1]Raw_Data!I21 -> TXN-0018 | J9: =PROPER(TRIM(CLEAN([1]Raw_Data!J21))) -> Quarterly Bonus | K9: =IF(COUNTIF($J$2:J9,J9)>1,"DUPLICATE","OK") -> OK | X9: =IF(COUNTIF(I9:I38,I9)>1,"Duplicate","Unique") -> Unique | AA9: =COUNTIF(I:I,I9) -> 1 | AB9: =COUNTIF(A:A,A9) -> 1 | AC9: =COUNTIFS(A:A,A9,I:I,I9) -> 1
A10: =IF(LEFT(TRIM([1]Raw_Data!A12),5)="CUST-",UPPER(TRIM([1]Raw_Data!A12)),"CUST-"&UPPER(TRIM([1]Raw_Data!A12))) -> CUST-1011 | B10: =[1]Raw_Data!B12 -> ACC-885953 | C10: =PROPER(TRIM(CLEAN([1]Raw_Data!C12))) -> Kavya Reddy | D10: =[1]Raw_Data!D12 -> 2026-08-11 | E10: =PROPER(TRIM([1]Raw_Data!E12)) -> Debit | F10: =IFERROR(VALUE(SUBSTITUTE(SUBSTITUTE(TRIM([1]Raw_Data!F12),"$",""),",","")),"CHECK") -> 750 | G10: =[1]Raw_Data!G12 -> INR | H10: =IF(TRIM([1]Raw_Data!H12)="","UNKNOWN",TRIM([1]Raw_Data!H12)) -> BRN-05 | I10: =[1]Raw_Data!I12 -> TXN-0011 | J10: =PROPER(TRIM(CLEAN([1]Raw_Data!J12))) -> Supermarket Purchase | K10: =IF(COUNTIF($J$2:J10,J10)>1,"DUPLICATE","OK") -> OK | X10: =IF(COUNTIF(I10:I39,I10)>1,"Duplicate","Unique") -> Unique | AA10: =COUNTIF(I:I,I10) -> 1 | AB10: =COUNTIF(A:A,A10) -> 1 | AC10: =COUNTIFS(A:A,A10,I:I,I10) -> 1
A11: =IF(LEFT(TRIM([1]Raw_Data!A27),5)="CUST-",UPPER(TRIM([1]Raw_Data!A27)),"CUST-"&UPPER(TRIM([1]Raw_Data!A27))) -> CUST-CUST -1024 | B11: =[1]Raw_Data!B27 -> ACC-442510 | C11: =PROPER(TRIM(CLEAN([1]Raw_Data!C27))) -> Kiran Bhat | D11: =[1]Raw_Data!D27 -> 2026-08-25 | E11: =PROPER(TRIM([1]Raw_Data!E27)) -> Credit | F11: =IFERROR(VALUE(SUBSTITUTE(SUBSTITUTE(TRIM([1]Raw_Data!F27),"$",""),",","")),"CHECK") -> 7200 | G11: =[1]Raw_Data!G27 -> INR | H11: =IF(TRIM([1]Raw_Data!H27)="","UNKNOWN",TRIM([1]Raw_Data!H27)) -> BRN-02 | I11: =[1]Raw_Data!I27 -> TXN-0024 | J11: =PROPER(TRIM(CLEAN([1]Raw_Data!J27))) -> Dividend Credit | K11: =IF(COUNTIF($J$2:J11,J11)>1,"DUPLICATE","OK") -> OK | X11: =IF(COUNTIF(I11:I40,I11)>1,"Duplicate","Unique") -> Unique | AA11: =COUNTIF(I:I,I11) -> 1 | AB11: =COUNTIF(A:A,A11) -> 1 | AC11: =COUNTIFS(A:A,A11,I:I,I11) -> 1
A12: =IF(LEFT(TRIM([1]Raw_Data!A20),5)="CUST-",UPPER(TRIM([1]Raw_Data!A20)),"CUST-"&UPPER(TRIM([1]Raw_Data!A20))) -> CUST-1017 | B12: =[1]Raw_Data!B20 -> ACC-119287 | C12: =PROPER(TRIM(CLEAN([1]Raw_Data!C20))) -> Lakshmi Rao | D12: =[1]Raw_Data!D20 -> 2026-08-19 | E12: =PROPER(TRIM([1]Raw_Data!E20)) -> Debit | F12: =IFERROR(VALUE(SUBSTITUTE(SUBSTITUTE(TRIM([1]Raw_Data!F20),"$",""),",","")),"CHECK") -> 1050 | G12: =[1]Raw_Data!G20 -> INR | H12: =IF(TRIM([1]Raw_Data!H20)="","UNKNOWN",TRIM([1]Raw_Data!H20)) -> BRN-05 | I12: =[1]Raw_Data!I20 -> TXN-0017 | J12: =PROPER(TRIM(CLEAN([1]Raw_Data!J20))) -> Mobile Recharge | K12: =IF(COUNTIF($J$2:J12,J12)>1,"DUPLICATE","OK") -> OK | X12: =IF(COUNTIF(I12:I41,I12)>1,"Duplicate","Unique") -> Unique | AA12: =COUNTIF(I:I,I12) -> 1 | AB12: =COUNTIF(A:A,A12) -> 1 | AC12: =COUNTIFS(A:A,A12,I:I,I12) -> 1
A13: =IF(LEFT(TRIM([1]Raw_Data!A10),5)="CUST-",UPPER(TRIM([1]Raw_Data!A10)),"CUST-"&UPPER(TRIM([1]Raw_Data!A10))) -> CUST-1009 | B13: =[1]Raw_Data!B10 -> ACC-007175 | C13: =PROPER(TRIM(CLEAN([1]Raw_Data!C10))) -> Meena Krishnan | D13: =[1]Raw_Data!D10 -> 2026-08-09 | E13: =PROPER(TRIM([1]Raw_Data!E10)) -> Debit | F13: =IFERROR(VALUE(SUBSTITUTE(SUBSTITUTE(TRIM([1]Raw_Data!F10),"$",""),",","")),"CHECK") -> 2300 | G13: =[1]Raw_Data!G10 -> INR | H13: =IF(TRIM([1]Raw_Data!H10)="","UNKNOWN",TRIM([1]Raw_Data!H10)) -> BRN-03 | I13: =[1]Raw_Data!I10 -> TXN-0009 | J13: =PROPER(TRIM(CLEAN([1]Raw_Data!J10))) -> Insurance Premium Paid | K13: =IF(COUNTIF($J$2:J13,J13)>1,"DUPLICATE","OK") -> OK | X13: =IF(COUNTIF(I13:I42,I13)>1,"Duplicate","Unique") -> Unique | AA13: =COUNTIF(I:I,I13) -> 1 | AB13: =COUNTIF(A:A,A13) -> 1 | AC13: =COUNTIFS(A:A,A13,I:I,I13) -> 1
A14: =IF(LEFT(TRIM([1]Raw_Data!A25),5)="CUST-",UPPER(TRIM([1]Raw_Data!A25)),"CUST-"&UPPER(TRIM([1]Raw_Data!A25))) -> CUST-1022 | B14: =[1]Raw_Data!B25 -> ACC-664732 | C14: =PROPER(TRIM(CLEAN([1]Raw_Data!C25))) -> Mohan Lal | D14: =[1]Raw_Data!D25 -> 2026-08-24 | E14: =PROPER(TRIM([1]Raw_Data!E25)) -> Debit | F14: =IFERROR(VALUE(SUBSTITUTE(SUBSTITUTE(TRIM([1]Raw_Data!F25),"$",""),",","")),"CHECK") -> 900 | G14: =[1]Raw_Data!G25 -> INR | H14: =IF(TRIM([1]Raw_Data!H25)="","UNKNOWN",TRIM([1]Raw_Data!H25)) -> BRN-04 | I14: =[1]Raw_Data!I25 -> TXN-0022 | J14: =PROPER(TRIM(CLEAN([1]Raw_Data!J25))) -> Book Purchase | K14: =IF(COUNTIF($J$2:J14,J14)>1,"DUPLICATE","OK") -> OK | X14: =IF(COUNTIF(I14:I43,I14)>1,"Duplicate","Unique") -> Unique | AA14: =COUNTIF(I:I,I14) -> 1 | AB14: =COUNTIF(A:A,A14) -> 1 | AC14: =COUNTIFS(A:A,A14,I:I,I14) -> 1
A15: =IF(LEFT(TRIM([1]Raw_Data!A16),5)="CUST-",UPPER(TRIM([1]Raw_Data!A16)),"CUST-"&UPPER(TRIM([1]Raw_Data!A16))) -> CUST-1014 | B15: =[1]Raw_Data!B16 -> ACC-442620 | C15: =PROPER(TRIM(CLEAN([1]Raw_Data!C16))) -> Nikhil Joshi | D15: =[1]Raw_Data!D16 -> 2026-08-15 | E15: =PROPER(TRIM([1]Raw_Data!E16)) -> Credit | F15: =IFERROR(VALUE(SUBSTITUTE(SUBSTITUTE(TRIM([1]Raw_Data!F16),"$",""),",","")),"CHECK") -> 18900 | G15: =[1]Raw_Data!G16 -> INR | H15: =IF(TRIM([1]Raw_Data!H16)="","UNKNOWN",TRIM([1]Raw_Data!H16)) -> BRN-01 | I15: =[1]Raw_Data!I16 -> TXN-0014 | J15: =PROPER(TRIM(CLEAN([1]Raw_Data!J16))) -> Consulting Fees | K15: =IF(COUNTIF($J$2:J15,J15)>1,"DUPLICATE","OK") -> OK | X15: =IF(COUNTIF(I15:I44,I15)>1,"Duplicate","Unique") -> Unique | AA15: =COUNTIF(I:I,I15) -> 1 | AB15: =COUNTIF(A:A,A15) -> 1 | AC15: =COUNTIFS(A:A,A15,I:I,I15) -> 1
A16: =IF(LEFT(TRIM([1]Raw_Data!A28),5)="CUST-",UPPER(TRIM([1]Raw_Data!A28)),"CUST-"&UPPER(TRIM([1]Raw_Data!A28))) -> CUST-1025 | B16: =[1]Raw_Data!B28 -> ACC-331399 | C16: =PROPER(TRIM(CLEAN([1]Raw_Data!C28))) -> Nisha Thomas | D16: =[1]Raw_Data!D28 -> 2026-08-25 | E16: =PROPER(TRIM([1]Raw_Data!E28)) -> Debit | F16: =IFERROR(VALUE(SUBSTITUTE(SUBSTITUTE(TRIM([1]Raw_Data!F28),"$",""),",","")),"CHECK") -> 350 | G16: =[1]Raw_Data!G28 -> INR | H16: =IF(TRIM([1]Raw_Data!H28)="","UNKNOWN",TRIM([1]Raw_Data!H28)) -> BRN-05 | I16: =[1]Raw_Data!I28 -> TXN-0025 | J16: =PROPER(TRIM(CLEAN([1]Raw_Data!J28))) -> Streaming Subscription | K16: =IF(COUNTIF($J$2:J16,J16)>1,"DUPLICATE","OK") -> OK | X16: =IF(COUNTIF(I16:I45,I16)>1,"Duplicate","Unique") -> Unique | AA16: =COUNTIF(I:I,I16) -> 1 | AB16: =COUNTIF(A:A,A16) -> 1 | AC16: =COUNTIFS(A:A,A16,I:I,I16) -> 1
A17: =IF(LEFT(TRIM([1]Raw_Data!A15),5)="CUST-",UPPER(TRIM([1]Raw_Data!A15)),"CUST-"&UPPER(TRIM([1]Raw_Data!A15))) -> CUST-1013 | B17: =[1]Raw_Data!B15 -> ACC-553731 | C17: =PROPER(TRIM(CLEAN([1]Raw_Data!C15))) -> Pooja Desai | D17: =[1]Raw_Data!D15 -> 2026-08-14 | E17: =PROPER(TRIM([1]Raw_Data!E15)) -> Debit | F17: =IFERROR(VALUE(SUBSTITUTE(SUBSTITUTE(TRIM([1]Raw_Data!F15),"$",""),",","")),"CHECK") -> 4200 | G17: =[1]Raw_Data!G15 -> INR | H17: =IF(TRIM([1]Raw_Data!H15)="","UNKNOWN",TRIM([1]Raw_Data!H15)) -> BRN-04 | I17: =[1]Raw_Data!I15 -> TXN-0013 | J17: =PROPER(TRIM(CLEAN([1]Raw_Data!J15))) -> Emi Payment | K17: =IF(COUNTIF($J$2:J17,J17)>1,"DUPLICATE","OK") -> OK | X17: =IF(COUNTIF(I17:I46,I17)>1,"Duplicate","Unique") -> Unique | AA17: =COUNTIF(I:I,I17) -> 1 | AB17: =COUNTIF(A:A,A17) -> 1 | AC17: =COUNTIFS(A:A,A17,I:I,I17) -> 1
A18: =IF(LEFT(TRIM([1]Raw_Data!A17),5)="CUST-",UPPER(TRIM([1]Raw_Data!A17)),"CUST-"&UPPER(TRIM([1]Raw_Data!A17))) -> CUST-1015 | B18: =[1]Raw_Data!B17 -> ACC-331509 | C18: =PROPER(TRIM(CLEAN([1]Raw_Data!C17))) -> Preethi Menon | D18: =[1]Raw_Data!D17 -> 2026-08-16 | E18: =PROPER(TRIM([1]Raw_Data!E17)) -> Debit | F18: =IFERROR(VALUE(SUBSTITUTE(SUBSTITUTE(TRIM([1]Raw_Data!F17),"$",""),",","")),"CHECK") -> 250 | G18: =[1]Raw_Data!G17 -> INR | H18: =IF(TRIM([1]Raw_Data!H17)="","UNKNOWN",TRIM([1]Raw_Data!H17)) -> UNKNOWN | I18: =[1]Raw_Data!I17 -> TXN-0015 | J18: =PROPER(TRIM(CLEAN([1]Raw_Data!J17))) -> Food Delivery | K18: =IF(COUNTIF($J$2:J18,J18)>1,"DUPLICATE","OK") -> OK | X18: =IF(COUNTIF(I18:I47,I18)>1,"Duplicate","Unique") -> Unique | AA18: =COUNTIF(I:I,I18) -> 1 | AB18: =COUNTIF(A:A,A18) -> 1 | AC18: =COUNTIFS(A:A,A18,I:I,I18) -> 1
A19: =IF(LEFT(TRIM([1]Raw_Data!A2),5)="CUST-",UPPER(TRIM([1]Raw_Data!A2)),"CUST-"&UPPER(TRIM([1]Raw_Data!A2))) -> CUST-1001 | B19: =[1]Raw_Data!B2 -> ACC-884521 | C19: =PROPER(TRIM(CLEAN([1]Raw_Data!C2))) -> Priya Sharma | D19: =[1]Raw_Data!D2 -> 2026-08-01 | E19: =PROPER(TRIM([1]Raw_Data!E2)) -> Credit | F19: =IFERROR(VALUE(SUBSTITUTE(SUBSTITUTE(TRIM([1]Raw_Data!F2),"$",""),",","")),"CHECK") -> 15000 | G19: =[1]Raw_Data!G2 -> INR | H19: =IF(TRIM([1]Raw_Data!H2)="","UNKNOWN",TRIM([1]Raw_Data!H2)) -> BRN-01 | I19: =[1]Raw_Data!I2 -> TXN-0001 | J19: =PROPER(TRIM(CLEAN([1]Raw_Data!J2))) -> Salary Credit For August | K19: =IF(COUNTIF($J$2:J19,J19)>1,"DUPLICATE","OK") -> OK | X19: =IF(COUNTIF(I19:I48,I19)>1,"Duplicate","Unique") -> Unique | AA19: =COUNTIF(I:I,I19) -> 1 | AB19: =COUNTIF(A:A,A19) -> 1 | AC19: =COUNTIFS(A:A,A19,I:I,I19) -> 1
A20: =IF(LEFT(TRIM([1]Raw_Data!A24),5)="CUST-",UPPER(TRIM([1]Raw_Data!A24)),"CUST-"&UPPER(TRIM([1]Raw_Data!A24))) -> CUST-1021 | B20: =[1]Raw_Data!B24 -> ACC-775843 | C20: =PROPER(TRIM(CLEAN([1]Raw_Data!C24))) -> Radha Krishna | D20: =[1]Raw_Data!D24 -> 2026-08-23 | E20: =PROPER(TRIM([1]Raw_Data!E24)) -> Credit | F20: =IFERROR(VALUE(SUBSTITUTE(SUBSTITUTE(TRIM([1]Raw_Data!F24),"$",""),",","")),"CHECK") -> 12750 | G20: =[1]Raw_Data!G24 -> INR | H20: =IF(TRIM([1]Raw_Data!H24)="","UNKNOWN",TRIM([1]Raw_Data!H24)) -> BRN-03 | I20: =[1]Raw_Data!I24 -> TXN-0021 | J20: =PROPER(TRIM(CLEAN([1]Raw_Data!J24))) -> Rental Income | K20: =IF(COUNTIF($J$2:J20,J20)>1,"DUPLICATE","OK") -> OK | X20: =IF(COUNTIF(I20:I49,I20)>1,"Duplicate","Unique") -> Unique | AA20: =COUNTIF(I:I,I20) -> 1 | AB20: =COUNTIF(A:A,A20) -> 1 | AC20: =COUNTIFS(A:A,A20,I:I,I20) -> 1
A21: =IF(LEFT(TRIM([1]Raw_Data!A3),5)="CUST-",UPPER(TRIM([1]Raw_Data!A3)),"CUST-"&UPPER(TRIM([1]Raw_Data!A3))) -> CUST-1002 | B21: =[1]Raw_Data!B3 -> ACC-774832 | C21: =PROPER(TRIM(CLEAN([1]Raw_Data!C3))) -> Rahul Mehta | D21: =[1]Raw_Data!D3 -> 2026-08-02 | E21: =PROPER(TRIM([1]Raw_Data!E3)) -> Debit | F21: =IFERROR(VALUE(SUBSTITUTE(SUBSTITUTE(TRIM([1]Raw_Data!F3),"$",""),",","")),"CHECK") -> 8500 | G21: =[1]Raw_Data!G3 -> INR | H21: =IF(TRIM([1]Raw_Data!H3)="","UNKNOWN",TRIM([1]Raw_Data!H3)) -> BRN-02 | I21: =[1]Raw_Data!I3 -> TXN-0002 | J21: =PROPER(TRIM(CLEAN([1]Raw_Data!J3))) -> Online Transfer To Vendor | K21: =IF(COUNTIF($J$2:J21,J21)>1,"DUPLICATE","OK") -> OK | X21: =IF(COUNTIF(I21:I50,I21)>1,"Duplicate","Unique") -> Duplicate | AA21: =COUNTIF(I:I,I21) -> 2 | AB21: =COUNTIF(A:A,A21) -> 2 | AC21: =COUNTIFS(A:A,A21,I:I,I21) -> 2
A22: =IF(LEFT(TRIM([1]Raw_Data!A19),5)="CUST-",UPPER(TRIM([1]Raw_Data!A19)),"CUST-"&UPPER(TRIM([1]Raw_Data!A19))) -> CUST-1002 | B22: =[1]Raw_Data!B19 -> ACC-774832 | C22: =PROPER(TRIM(CLEAN([1]Raw_Data!C19))) -> Rahul Mehta | D22: =[1]Raw_Data!D19 -> 2026-08-02 | E22: =PROPER(TRIM([1]Raw_Data!E19)) -> Debit | F22: =IFERROR(VALUE(SUBSTITUTE(SUBSTITUTE(TRIM([1]Raw_Data!F19),"$",""),",","")),"CHECK") -> 8500 | G22: =[1]Raw_Data!G19 -> INR | H22: =IF(TRIM([1]Raw_Data!H19)="","UNKNOWN",TRIM([1]Raw_Data!H19)) -> BRN-02 | I22: =[1]Raw_Data!I19 -> TXN-0002 | J22: =PROPER(TRIM(CLEAN([1]Raw_Data!J19))) -> Online Transfer To Vendor | K22: =IF(COUNTIF($J$2:J22,J22)>1,"DUPLICATE","OK") -> DUPLICATE | X22: =IF(COUNTIF(I22:I51,I22)>1,"Duplicate","Unique") -> Unique | AA22: =COUNTIF(I:I,I22) -> 2 | AB22: =COUNTIF(A:A,A22) -> 2 | AC22: =COUNTIFS(A:A,A22,I:I,I22) -> 2
A23: =IF(LEFT(TRIM([1]Raw_Data!A31),5)="CUST-",UPPER(TRIM([1]Raw_Data!A31)),"CUST-"&UPPER(TRIM([1]Raw_Data!A31))) -> CUST-1028 | B23: =[1]Raw_Data!B31 -> ACC-008066 | C23: =PROPER(TRIM(CLEAN([1]Raw_Data!C31))) -> Rajan Pillai | D23: =[1]Raw_Data!D31 -> 25/08/2026 | E23: =PROPER(TRIM([1]Raw_Data!E31)) -> Credit | F23: =IFERROR(VALUE(SUBSTITUTE(SUBSTITUTE(TRIM([1]Raw_Data!F31),"$",""),",","")),"CHECK") -> 14000 | G23: =[1]Raw_Data!G31 -> INR | H23: =IF(TRIM([1]Raw_Data!H31)="","UNKNOWN",TRIM([1]Raw_Data!H31)) -> BRN-04 | I23: =[1]Raw_Data!I31 -> TXN-0028 | J23: =PROPER(TRIM(CLEAN([1]Raw_Data!J31))) -> Salary Advance | K23: =IF(COUNTIF($J$2:J23,J23)>1,"DUPLICATE","OK") -> OK | X23: =IF(COUNTIF(I23:I52,I23)>1,"Duplicate","Unique") -> Unique | AA23: =COUNTIF(I:I,I23) -> 1 | AB23: =COUNTIF(A:A,A23) -> 1 | AC23: =COUNTIFS(A:A,A23,I:I,I23) -> 1
A24: =IF(LEFT(TRIM([1]Raw_Data!A8),5)="CUST-",UPPER(TRIM([1]Raw_Data!A8)),"CUST-"&UPPER(TRIM([1]Raw_Data!A8))) -> CUST-1007 | B24: =[1]Raw_Data!B8 -> ACC-229397 | C24: =PROPER(TRIM(CLEAN([1]Raw_Data!C8))) -> Ritu Gupta | D24: =[1]Raw_Data!D8 -> 2026-08-07 | E24: =PROPER(TRIM([1]Raw_Data!E8)) -> Debit | F24: =IFERROR(VALUE(SUBSTITUTE(SUBSTITUTE(TRIM([1]Raw_Data!F8),"$",""),",","")),"CHECK") -> 500 | G24: =[1]Raw_Data!G8 -> INR | H24: =IF(TRIM([1]Raw_Data!H8)="","UNKNOWN",TRIM([1]Raw_Data!H8)) -> BRN-04 | I24: =[1]Raw_Data!I8 -> TXN-0007 | J24: =PROPER(TRIM(CLEAN([1]Raw_Data!J8))) -> Coffee Shop Payment | K24: =IF(COUNTIF($J$2:J24,J24)>1,"DUPLICATE","OK") -> OK | X24: =IF(COUNTIF(I24:I53,I24)>1,"Duplicate","Unique") -> Unique | AA24: =COUNTIF(I:I,I24) -> 1 | AB24: =COUNTIF(A:A,A24) -> 1 | AC24: =COUNTIFS(A:A,A24,I:I,I24) -> 1
A25: =IF(LEFT(TRIM([1]Raw_Data!A18),5)="CUST-",UPPER(TRIM([1]Raw_Data!A18)),"CUST-"&UPPER(TRIM([1]Raw_Data!A18))) -> CUST-1016 | B25: =[1]Raw_Data!B18 -> ACC-220398 | C25: =PROPER(TRIM(CLEAN([1]Raw_Data!C18))) -> Rohit Kumar | D25: =[1]Raw_Data!D18 -> 2026-08-17 | E25: =PROPER(TRIM([1]Raw_Data!E18)) -> Credit | F25: =IFERROR(VALUE(SUBSTITUTE(SUBSTITUTE(TRIM([1]Raw_Data!F18),"$",""),",","")),"CHECK") -> 8000 | G25: =[1]Raw_Data!G18 -> INR | H25: =IF(TRIM([1]Raw_Data!H18)="","UNKNOWN",TRIM([1]Raw_Data!H18)) -> BRN-03 | I25: =[1]Raw_Data!I18 -> TXN-0016 | J25: =PROPER(TRIM(CLEAN([1]Raw_Data!J18))) -> Part-Time Income | K25: =IF(COUNTIF($J$2:J25,J25)>1,"DUPLICATE","OK") -> OK | X25: =IF(COUNTIF(I25:I54,I25)>1,"Duplicate","Unique") -> Unique | AA25: =COUNTIF(I:I,I25) -> 1 | AB25: =COUNTIF(A:A,A25) -> 1 | AC25: =COUNTIFS(A:A,A25,I:I,I25) -> 1
A26: =IF(LEFT(TRIM([1]Raw_Data!A23),5)="CUST-",UPPER(TRIM([1]Raw_Data!A23)),"CUST-"&UPPER(TRIM([1]Raw_Data!A23))) -> CUST-1020 | B26: =[1]Raw_Data!B23 -> ACC-886954 | C26: =PROPER(TRIM(CLEAN([1]Raw_Data!C23))) -> Sanjay Kapoor | D26: =[1]Raw_Data!D23 -> 2026-08-22 | E26: =PROPER(TRIM([1]Raw_Data!E23)) -> Credit | F26: =IFERROR(VALUE(SUBSTITUTE(SUBSTITUTE(TRIM([1]Raw_Data!F23),"$",""),",","")),"CHECK") -> 5500 | G26: =[1]Raw_Data!G23 -> INR | H26: =IF(TRIM([1]Raw_Data!H23)="","UNKNOWN",TRIM([1]Raw_Data!H23)) -> BRN-01 | I26: =[1]Raw_Data!I23 -> TXN-0020 | J26: =PROPER(TRIM(CLEAN([1]Raw_Data!J23))) -> Freelance Invoice | K26: =IF(COUNTIF($J$2:J26,J26)>1,"DUPLICATE","OK") -> OK | X26: =IF(COUNTIF(I26:I55,I26)>1,"Duplicate","Unique") -> Unique | AA26: =COUNTIF(I:I,I26) -> 1 | AB26: =COUNTIF(A:A,A26) -> 1 | AC26: =COUNTIFS(A:A,A26,I:I,I26) -> 1
A27: =IF(LEFT(TRIM([1]Raw_Data!A6),5)="CUST-",UPPER(TRIM([1]Raw_Data!A6)),"CUST-"&UPPER(TRIM([1]Raw_Data!A6))) -> CUST-1005 | B27: =[1]Raw_Data!B6 -> ACC-441519 | C27: =PROPER(TRIM(CLEAN([1]Raw_Data!C6))) -> Sneha Nair | D27: =[1]Raw_Data!D6 -> 2026-08-05 | E27: =PROPER(TRIM([1]Raw_Data!E6)) -> Credit | F27: =IFERROR(VALUE(SUBSTITUTE(SUBSTITUTE(TRIM([1]Raw_Data!F6),"$",""),",","")),"CHECK") -> 9800 | G27: =[1]Raw_Data!G6 -> INR | H27: =IF(TRIM([1]Raw_Data!H6)="","UNKNOWN",TRIM([1]Raw_Data!H6)) -> BRN-03 | I27: =[1]Raw_Data!I6 -> TXN-0003 | J27: =PROPER(TRIM(CLEAN([1]Raw_Data!J6))) -> Freelance Payment Received | K27: =IF(COUNTIF($J$2:J27,J27)>1,"DUPLICATE","OK") -> OK | X27: =IF(COUNTIF(I27:I56,I27)>1,"Duplicate","Unique") -> Unique | AA27: =COUNTIF(I:I,I27) -> 3 | AB27: =COUNTIF(A:A,A27) -> 1 | AC27: =COUNTIFS(A:A,A27,I:I,I27) -> 1
A28: =IF(LEFT(TRIM([1]Raw_Data!A30),5)="CUST-",UPPER(TRIM([1]Raw_Data!A30)),"CUST-"&UPPER(TRIM([1]Raw_Data!A30))) -> CUST-1027 | B28: =[1]Raw_Data!B30 -> ACC-119177 | C28: =PROPER(TRIM(CLEAN([1]Raw_Data!C30))) -> Sunita Rao | D28: =[1]Raw_Data!D30 -> 2026-08-25 | E28: =PROPER(TRIM([1]Raw_Data!E30)) -> Debit | F28: =IFERROR(VALUE(SUBSTITUTE(SUBSTITUTE(TRIM([1]Raw_Data!F30),"$",""),",","")),"CHECK") -> 1800 | G28: =[1]Raw_Data!G30 -> INR | H28: =IF(TRIM([1]Raw_Data!H30)="","UNKNOWN",TRIM([1]Raw_Data!H30)) -> BRN-03 | I28: =[1]Raw_Data!I30 -> TXN-0027 | J28: =PROPER(TRIM(CLEAN([1]Raw_Data!J30))) -> Monthly Subscription | K28: =IF(COUNTIF($J$2:J28,J28)>1,"DUPLICATE","OK") -> OK | X28: =IF(COUNTIF(I28:I57,I28)>1,"Duplicate","Unique") -> Unique | AA28: =COUNTIF(I:I,I28) -> 1 | AB28: =COUNTIF(A:A,A28) -> 1 | AC28: =COUNTIFS(A:A,A28,I:I,I28) -> 1
A29: =IF(LEFT(TRIM([1]Raw_Data!A13),5)="CUST-",UPPER(TRIM([1]Raw_Data!A13)),"CUST-"&UPPER(TRIM([1]Raw_Data!A13))) -> CUST-1012 | B29: =[1]Raw_Data!B13 -> ACC-774842 | C29: =PROPER(TRIM(CLEAN([1]Raw_Data!C13))) -> Suresh Pillai | D29: =[1]Raw_Data!D13 -> 2026-08-12 | E29: =PROPER(TRIM([1]Raw_Data!E13)) -> Credit | F29: =IFERROR(VALUE(SUBSTITUTE(SUBSTITUTE(TRIM([1]Raw_Data!F13),"$",""),",","")),"CHECK") -> CHECK | G29: =[1]Raw_Data!G13 -> INR | H29: =IF(TRIM([1]Raw_Data!H13)="","UNKNOWN",TRIM([1]Raw_Data!H13)) -> BRN-02 | I29: =[1]Raw_Data!I13 -> TXN-0012 | J29: =PROPER(TRIM(CLEAN([1]Raw_Data!J13))) -> Pending Credit | K29: =IF(COUNTIF($J$2:J29,J29)>1,"DUPLICATE","OK") -> OK | X29: =IF(COUNTIF(I29:I58,I29)>1,"Duplicate","Unique") -> Unique | AA29: =COUNTIF(I:I,I29) -> 1 | AB29: =COUNTIF(A:A,A29) -> 1 | AC29: =COUNTIFS(A:A,A29,I:I,I29) -> 1
A30: =IF(LEFT(TRIM([1]Raw_Data!A5),5)="CUST-",UPPER(TRIM([1]Raw_Data!A5)),"CUST-"&UPPER(TRIM([1]Raw_Data!A5))) -> CUST-1004 | B30: =[1]Raw_Data!B5 -> ACC-552630 | C30: =PROPER(TRIM(CLEAN([1]Raw_Data!C5))) -> Vikram Singh | D30: =[1]Raw_Data!D5 -> 2026-08-04 | E30: =PROPER(TRIM([1]Raw_Data!E5)) -> Debit | F30: =IFERROR(VALUE(SUBSTITUTE(SUBSTITUTE(TRIM([1]Raw_Data!F5),"$",""),",","")),"CHECK") -> 3750 | G30: =[1]Raw_Data!G5 -> INR | H30: =IF(TRIM([1]Raw_Data!H5)="","UNKNOWN",TRIM([1]Raw_Data!H5)) -> BRN-01 | I30: =[1]Raw_Data!I5 -> TXN-0004 | J30: =PROPER(TRIM(CLEAN([1]Raw_Data!J5))) -> Atm Withdrawal | K30: =IF(COUNTIF($J$2:J30,J30)>1,"DUPLICATE","OK") -> OK | X30: =IF(COUNTIF(I30:I59,I30)>1,"Duplicate","Unique") -> Unique | AA30: =COUNTIF(I:I,I30) -> 1 | AB30: =COUNTIF(A:A,A30) -> 1 | AC30: =COUNTIFS(A:A,A30,I:I,I30) -> 1
A31: =IF(LEFT(TRIM([1]Raw_Data!A29),5)="CUST-",UPPER(TRIM([1]Raw_Data!A29)),"CUST-"&UPPER(TRIM([1]Raw_Data!A29))) -> CUST-1026 | B31: =[1]Raw_Data!B29 -> ACC-220288 | C31: =PROPER(TRIM(CLEAN([1]Raw_Data!C29))) -> Vishal Agarwal | D31: =[1]Raw_Data!D29 -> 2026-08-25 | E31: =PROPER(TRIM([1]Raw_Data!E29)) -> Credit | F31: =IFERROR(VALUE(SUBSTITUTE(SUBSTITUTE(TRIM([1]Raw_Data!F29),"$",""),",","")),"CHECK") -> 25000 | G31: =[1]Raw_Data!G29 -> INR | H31: =IF(TRIM([1]Raw_Data!H29)="","UNKNOWN",TRIM([1]Raw_Data!H29)) -> BRN-01 | I31: =[1]Raw_Data!I29 -> TXN-0026 | J31: =PROPER(TRIM(CLEAN([1]Raw_Data!J29))) -> Project Bonus | K31: =IF(COUNTIF($J$2:J31,J31)>1,"DUPLICATE","OK") -> OK | X31: =IF(COUNTIF(I31:I60,I31)>1,"Duplicate","Unique") -> Unique | AA31: =COUNTIF(I:I,I31) -> 1 | AB31: =COUNTIF(A:A,A31) -> 1 | AC31: =COUNTIFS(A:A,A31,I:I,I31) -> 1
AA32: =COUNTIF(I:I,I32) -> 0 | AB32: =COUNTIF(A:A,A32) -> 0 | AC32: =COUNTIFS(A:A,A32,I:I,I32) -> 0
A33: 💡 Blue cells = Excel formulas (click to see) | After removing duplicates from Raw_Data, re-check which rows disappear here | Column D (Date): practice Text-to-Columns & date formatting manually in Excel

Sheet Raw_Data
A1: Customer_ID | B1: Account_Number | C1: Customer_Name | D1: Transaction_Date | E1: Transaction_Type | F1: Amount | G1: Currency | H1: Branch_Code | I1: Transaction_ID | J1: Notes | K1: Name_DOB_Combined | M1: Date | N1: Check Date
A2: CUST-1001 | B2: ACC-884521 | C2: Priya Sharma | D2: 2026-08-01 | E2: Credit | F2: 15000 | G2: INR | H2: BRN-01 | I2: TXN-0001 | J2: Salary credit for August | K2: Priya Sharma | 1990-04-12 | M2: 01/08/2026 | N2: =IF(ISNUMBER(M2),"Valid Date","Not a Date") -> Not a Date
A3: CUST-1002 | B3: ACC-774832 | C3: RAHUL MEHTA | D3: 2026-08-02 | E3: DEBIT | F3: $8,500.00 | G3: INR | H3: BRN-02 | I3: TXN-0002 | J3: Online transfer to vendor | K3: RAHUL MEHTA | 1985-11-30
A4: 1003 | B4: ACC-663741 | C4: ananya iyer | D4: 01/08/2026 | E4: credit | F4: 22000 | G4: INR | I4: TXN-0003 | J4: Loan disbursement [SYS] | K4: ananya iyer | 1993-07-08
A5: CUST-1004 | B5: ACC-552630 | C5: Vikram Singh | D5: 2026-08-04 | E5: Debit | F5: 3750 | G5: INR | H5: BRN-01 | I5: TXN-0004 | J5: ATM withdrawal | K5: Vikram Singh | 1978-02-25
A6: CUST-1005 | B6: ACC-441519 | C6: Sneha Nair | D6: 2026-08-05 | E6: Credit | F6: 9800 | G6: INR | H6: BRN-03 | I6: TXN-0003 | J6: Freelance payment received | K6: Sneha Nair | 1995-09-14
A7: CUST -1006 | B7: ACC-330408 | C7: AMIT PATEL | D7: 2026-08-06 | E7: DEBIT | F7: 1,200.50 | G7: INR | H7: BRN-02 | I7: TXN-0006 | J7: Utility bill payment | K7: AMIT PATEL | 1982-06-03
A8: CUST-1007 | B8: ACC-229397 | C8: ritu gupta | D8: 2026-08-07 | E8: debit | F8: 500 | G8: INR | H8: BRN-04 | I8: TXN-0007 | J8: Coffee shop payment | K8: ritu gupta | 1999-12-20
A9: CUST-1008 | B9: ACC-118286 | C9: Deepak Verma | D9: 08-Aug-2026 | E9: Credit | F9: $45,000 | G9: INR | I9: TXN-0008 | J9: Property rent collected extra | K9: Deepak Verma | 1975-03-17
A10: CUST-1009 | B10: ACC-007175 | C10: MEENA KRISHNAN | D10: 2026-08-09 | E10: Debit | F10: $2,300.00 | G10: INR | H10: BRN-03 | I10: TXN-0009 | J10: Insurance premium paid | K10: MEENA KRISHNAN | 1988-08-05
A11: CUST-1010 | B11: ACC-996064 | C11: Arjun Bose | D11: 2026-08-10 | E11: Credit | F11: 11000 | G11: INR | H11: BRN-01 | I11: TXN-0010 | J11: Dividend received | K11: Arjun Bose | 1991-01-22
A12: 1011 | B12: ACC-885953 | C12: kavya reddy | D12: 2026-08-11 | E12: debit | F12: 750 | G12: INR | H12: BRN-05 | I12: TXN-0011 | J12: Supermarket purchase | K12: kavya reddy | 1996-05-09
A13: CUST-1012 | B13: ACC-774842 | C13: SURESH PILLAI | D13: 2026-08-12 | E13: Credit | F13: N/A | G13: INR | H13: BRN-02 | I13: TXN-0012 | J13: Pending credit | K13: SURESH PILLAI | 1970-10-31
A14: 1003 | B14: ACC-663741 | C14: ananya iyer | D14: 01/08/2026 | E14: credit | F14: 22000 | G14: INR | I14: TXN-0003 | J14: Loan disbursement | K14: ananya iyer | 1993-07-08
A15: CUST-1013 | B15: ACC-553731 | C15: Pooja Desai | D15: 2026-08-14 | E15: Debit | F15: 4200 | G15: INR | H15: BRN-04 | I15: TXN-0013 | J15: EMI payment | K15: Pooja Desai | 1987-02-14
A16: CUST-1014 | B16: ACC-442620 | C16: NIKHIL JOSHI | D16: 2026-08-15 | E16: CREDIT | F16: $18,900 | G16: INR | H16: BRN-01 | I16: TXN-0014 | J16: Consulting fees | K16: NIKHIL JOSHI | 1983-07-07
A17: 1015 | B17: ACC-331509 | C17: preethi menon | D17: 2026-08-16 | E17: debit | F17: 250 | G17: INR | I17: TXN-0015 | J17: Food delivery | K17: preethi menon | 2000-11-11
A18: CUST-1016 | B18: ACC-220398 | C18: Rohit Kumar | D18: 2026-08-17 | E18: Credit | F18: 8000 | G18: INR | H18: BRN-03 | I18: TXN-0016 | J18: Part-time income | K18: Rohit Kumar | 1994-08-19
A19: CUST-1002 | B19: ACC-774832 | C19: RAHUL MEHTA | D19: 2026-08-02 | E19: DEBIT | F19: $8,500.00 | G19: INR | H19: BRN-02 | I19: TXN-0002 | J19: Online transfer to vendor | K19: RAHUL MEHTA | 1985-11-30
A20: CUST-1017 | B20: ACC-119287 | C20: LAKSHMI RAO | D20: 2026-08-19 | E20: Debit | F20: 1,050 | G20: INR | H20: BRN-05 | I20: TXN-0017 | J20: Mobile recharge | K20: LAKSHMI RAO | 1979-04-28
A21: CUST-1018 | B21: ACC-008176 | C21: Harsh Vardhan | D21: 2026-08-20 | E21: Credit | F21: 30000 | G21: INR | H21: BRN-02 | I21: TXN-0018 | J21: Quarterly bonus | K21: Harsh Vardhan | 1986-09-16
A22: CUST-1019 | B22: ACC-997065 | C22: DIVYA NAMBIAR | D22: 21-Aug-2026 | E22: DEBIT | F22: $600 | G22: INR | I22: TXN-0019 | J22: Grocery shopping | K22: DIVYA NAMBIAR | 1992-03-03
A23: CUST-1020 | B23: ACC-886954 | C23: sanjay kapoor | D23: 2026-08-22 | E23: credit | F23: 5500 | G23: INR | H23: BRN-01 | I23: TXN-0020 | J23: Freelance invoice | K23: sanjay kapoor | 1989-12-25
A24: CUST-1021 | B24: ACC-775843 | C24: RADHA KRISHNA | D24: 2026-08-23 | E24: Credit | F24: 12,750 | G24: INR | H24: BRN-03 | I24: TXN-0021 | J24: Rental income | K24: RADHA KRISHNA | 1976-06-30
A25: 1022 | B25: ACC-664732 | C25: mohan lal | D25: 2026-08-24 | E25: debit | F25: 900 | G25: INR | H25: BRN-04 | I25: TXN-0022 | J25: Book purchase | K25: mohan lal | 1998-01-15
A26: CUST-1023 | B26: ACC-553621 | C26: Geeta Pillai | D26: 2026-08-25 | E26: Debit | F26: 2100 | G26: INR | I26: TXN-0023 | J26: School fees | K26: Geeta Pillai | 1984-05-02
A27: CUST -1024 | B27: ACC-442510 | C27: KIRAN BHAT | D27: 2026-08-25 | E27: CREDIT | F27: $7,200.00 | G27: INR | H27: BRN-02 | I27: TXN-0024 | J27: Dividend credit | K27: KIRAN BHAT | 1981-08-21
A28: CUST-1025 | B28: ACC-331399 | C28: nisha thomas | D28: 2026-08-25 | E28: debit | F28: $350 | G28: INR | H28: BRN-05 | I28: TXN-0025 | J28: Streaming subscription | K28: nisha thomas | 2001-03-07
A29: CUST-1026 | B29: ACC-220288 | C29: VISHAL AGARWAL | D29: 2026-08-25 | E29: Credit | F29: 25000 | G29: INR | H29: BRN-01 | I29: TXN-0026 | J29: Project bonus | K29: VISHAL AGARWAL | 1977-11-18
A30: CUST-1027 | B30: ACC-119177 | C30: Sunita Rao | D30: 2026-08-25 | E30: Debit | F30: 1800 | G30: INR | H30: BRN-03 | I30: TXN-0027 | J30: Monthly subscription | K30: Sunita Rao | 1993-06-06
A31: 1028 | B31: ACC-008066 | C31: rajan pillai | D31: 25/08/2026 | E31: credit | F31: 14000 | G31: INR | H31: BRN-04 | I31: TXN-0028 | J31: Salary advance | K31: rajan pillai | 1980-09-29
A33: LEGEND: 🔴 Pink fill = Duplicate row | 🟡 Yellow fill = Blank value | 🟠 Orange text = Inconsistent format | Find hidden chars & spacing issues in Notes column
D34: IsNumbe

Sheet Cleaned_Data
